Workbook

Sheet Raw Data
A1: OrderID | B1: Date | C1: CustomerID | D1: Product | E1: Quantity | F1: UnitPrice | G1: ShippingAddress | H1: PaymentMethod | I1: OrderStatus | J1: TrackingNumber | K1: ItemsInCart | L1: CouponCode | M1: ReferralSource | N1: TotalPrice
A2: ORD200000 | B2: 44930 | C2: C72649 | D2: Monitor | E2: 5 | F2: 570.62 | G2: 928 Main St | H2: Debit Card | I2: Shipped | J2: TRK37947903 | K2: 7 | L2: SAVE10 | M2: Instagram | N2: 2853.1
A3: ORD200001 | B3: 45527 | C3: C75739 | D3: Phone | E3: 2 | F3: 151.35 | G3: 823 Main St | H3: Online | I3: Shipped | J3: TRK91186779 | K3: 3 | L3: SAVE10 | M3: Referral | N3: 302.7
A4: ORD200002 | B4: 45349 | C4: C81728 | D4: Tablet | E4: 5 | F4: 550.68 | G4: 512 Main St | H4: Credit Card | I4: Cancelled | J4: TRK42903982 | K4: 8 | L4: FREESHIP | M4: Email | N4: 2753.4
A5: ORD200003 | B5: 45214 | C5: C33540 | D5: Chair | E5: 1 | F5: 273.19 | G5: 275 Main St | H5: Debit Card | I5: Returned | J5: TRK62788070 | K5: 5 | L5: SAVE10 | M5: Facebook | N5: 273.19
A6: ORD200004 | B6: 45785 | C6: C81840 | D6: Printer | E6: 4 | F6: 626.01 | G6: 668 Main St | H6: Online | I6: Delivered | J6: TRK29241424 | K6: 8 | L6: SAVE10 | M6: Email | N6: 2504.04
A7: ORD200005 | B7: 45222 | C7: C37249 | D7: Phone | E7: 2 | F7: 245.86 | G7: 934 Main St | H7: Credit Card | I7: Shipped | J7: TRK72976927 | K7: 4 | L7: SAVE10 | M7: Instagram | N7: 491.72
A8: ORD200006 | B8: 45825 | C8: C83492 | D8: Laptop | E8: 1 | F8: 664.42 | G8: 986 Main St | H8: Gift Card | I8: Returned | J8: TRK96417362 | K8: 6 | L8: SAVE10 | M8: Facebook | N8: 664.42
A9: ORD200007 | B9: 45058 | C9: C41460 | D9: Monitor | E9: 5 | F9: 149.55 | G9: 706 Main St | H9: Cash | I9: Shipped | J9: TRK78809193 | K9: 9 | L9: FREESHIP | M9: Facebook | N9: 747.75
A10: ORD200008 | B10: 45749 | C10: C26817 | D10: Phone | E10: 2 | F10: 134.28 | G10: 904 Main St | H10: Gift Card | I10: Cancelled | J10: TRK61042692 | K10: 2 | M10: Email | N10: 268.56
A11: ORD200009 | B11: 45251 | C11: C31946 | D11: Desk | E11: 4 | F11: 509.38 | G11: 102 Main St | H11: Credit Card | I11: Shipped | J11: TRK33478363 | K11: 6 | L11: SAVE10 | M11: Google | N11: 2037.52
A12: ORD200010 | B12: 45289 | C12: C43443 | D12: Tablet | E12: 5 | F12: 625.97 | G12: 333 Main St | H12: Credit Card | I12: Returned | J12: TRK98859248 | K12: 9 | L12: WINTER15 | M12: Instagram | N12: 3129.85
A13: ORD200011 | B13: 45339 | C13: C93861 | D13: Monitor | E13: 3 | F13: 49.14 | G13: 831 Main St | H13: Online | I13: Returned | J13: TRK48234646 | K13: 7 | L13: SAVE10 | M13: Email | N13: 147.42
A14: ORD200012 | B14: 45580 | C14: C38785 | D14: Monitor | E14: 2 | F14: 180.5 | G14: 179 Main St | H14: Debit Card | I14: Pending | J14: TRK20419991 | K14: 6 | L14: FREESHIP | M14: Referral | N14: 361
A15: ORD200013 | B15: 45168 | C15: C88348 | D15: Laptop | E15: 3 | F15: 201.49 | G15: 903 Main St | H15: Credit Card | I15: Returned | J15: TRK81913874 | K15: 4 | L15: FREESHIP | M15: Facebook | N15: 604.47
A16: ORD200014 | B16: 45012 | C16: C98474 | D16: Tablet | E16: 2 | F16: 393.33 | G16: 980 Main St | H16: Debit Card | I16: Pending | J16: TRK79186539 | K16: 3 | L16: SAVE10 | M16: Instagram | N16: 786.66
A17: ORD200015 | B17: 45124 | C17: C39416 | D17: Printer | E17: 1 | F17: 473.96 | G17: 942 Main St | H17: Cash | I17: Delivered | J17: TRK54930938 | K17: 3 | M17: Google | N17: 473.96
A18: ORD200016 | B18: 44950 | C18: C28976 | D18: Printer | E18: 2 | F18: 533.81 | G18: 914 Main St | H18: Credit Card | I18: Pending | J18: TRK13194259 | K18: 3 | L18: FREESHIP | M18: Email | N18: 1067.62
A19: ORD200017 | B19: 45353 | C19: C60672 | D19: Tablet | E19: 1 | F19: 423.4 | G19: 382 Main St | H19: Debit Card | I19: Shipped | J19: TRK11972116 | K19: 3 | M19: Referral | N19: 423.4
A20: ORD200018 | B20: 45742 | C20: C84329 | D20: Desk | E20: 1 | F20: 431.44 | G20: 891 Main St | H20: Gift Card | I20: Pending | J20: TRK65191045 | K20: 3 | L20: SAVE10 | M20: Facebook | N20: 431.44
A21: ORD200019 | B21: 44949 | C21: C14552 | D21: Monitor | E21: 5 | F21: 224 | G21: 273 Main St | H21: Cash | I21: Returned | J21: TRK59101365 | K21: 9 | L21: SAVE10 | M21: Google | N21: 1120
A22: ORD200020 | B22: 45054 | C22: C54829 | D22: Chair | E22: 5 | F22: 62.51 | G22: 587 Main St | H22: Cash | I22: Pending | J22: TRK16718651 | K22: 9 | L22: WINTER15 | M22: Instagram | N22: 312.55
A23: ORD200021 | B23: 45613 | C23: C99023 | D23: Monitor | E23: 4 | F23: 342.95 | G23: 569 Main St | H23: Cash | I23: Delivered | J23: TRK52646983 | K23: 6 | M23: Google | N23: 1371.8
A24: ORD200022 | B24: 44955 | C24: C34416 | D24: Monitor | E24: 2 | F24: 49.62 | G24: 633 Main St | H24: Online | I24: Pending | J24: TRK75937350 | K24: 2 | L24: SAVE10 | M24: Google | N24: 99.24
A25: ORD200023 | B25: 45756 | C25: C42372 | D25: Phone | E25: 4 | F25: 273.25 | G25: 755 Main St | H25: Debit Card | I25: Cancelled | J25: TRK36168083 | K25: 5 | L25: FREESHIP | M25: Referral | N25: 1093
A26: ORD200024 | B26: 45595 | C26: C17470 | D26: Laptop | E26: 2 | F26: 230.95 | G26: 956 Main St | H26: Online | I26: Delivered | J26: TRK28775057 | K26: 3 | L26: WINTER15 | M26: Referral | N26: 461.9
A27: ORD200025 | B27: 45497 | C27: C42577 | D27: Monitor | E27: 1 | F27: 399.98 | G27: 709 Main St | H27: Debit Card | I27: Delivered | J27: TRK69423327 | K27: 3 | L27: WINTER15 | M27: Email | N27: 399.98
A28: ORD200026 | B28: 45357 | C28: C21944 | D28: Laptop | E28: 5 | F28: 59.55 | G28: 296 Main St | H28: Online | I28: Delivered | J28: TRK80276812 | K28: 6 | M28: Referral | N28: 297.75
A29: ORD200027 | B29: 45344 | C29: C97593 | D29: Printer | E29: 1 | F29: 472.74 | G29: 881 Main St | H29: Online | I29: Shipped | J29: TRK89117573 | K29: 6 | L29: WINTER15 | M29: Google | N29: 472.74
A30: ORD200028 | B30: 45251 | C30: C59823 | D30: Phone | E30: 4 | F30: 160.07 | G30: 568 Main St | H30: Online | I30: Pending | J30: TRK65895539 | K30: 5 | M30: Email | N30: 640.28
A31: ORD200029 | B31: 45555 | C31: C33260 | D31: Desk | E31: 3 | F31: 423.53 | G31: 930 Main St | H31: Credit Card | I31: Delivered | J31: TRK59744090 | K31: 6 | L31: SAVE10 | M31: Referral | N31: 1270.59
A32: ORD200030 | B32: 45738 | C32: C44267 | D32: Monitor | E32: 2 | F32: 426.7 | G32: 895 Main St | H32: Online | I32: Pending | J32: TRK54751444 | K32: 5 | L32: SAVE10 | M32: Referral | N32: 853.4
A33: ORD200031 | B33: 45107 | C33: C26445 | D33: Chair | E33: 3 | F33: 500.08 | G33: 996 Main St | H33: Debit Card | I33: Returned | J33: TRK31229981 | K33: 6 | M33: Facebook | N33: 1500.24
A34: ORD200032 | B34: 45047 | C34: C12388 | D34: Tablet | E34: 5 | F34: 536.72 | G34: 830 Main St | H34: Cash | I34: Delivered | J34: TRK99261395 | K34: 10 | M34: Email | N34: 2683.6
A35: ORD200033 | B35: 45082 | C35: C52184 | D35: Chair | E35: 1 | F35: 162.77 | G35: 912 Main St | H35: Online | I35: Cancelled | J35: TRK73312471 | K35: 4 | L35: WINTER15 | M35: Facebook | N35: 162.77
A36: ORD200034 | B36: 44933 | C36: C67195 | D36: Chair | E36: 4 | F36: 576.52 | G36: 926 Main St | H36: Credit Card | I36: Pending | J36: TRK55467915 | K36: 5 | L36: WINTER15 | M36: Facebook | N36: 2306.08
A37: ORD200035 | B37: 45633 | C37: C50304 | D37: Monitor | E37: 2 | F37: 465.15 | G37: 128 Main St | H37: Online | I37: Shipped | J37: TRK46850888 | K37: 2 | L37: SAVE10 | M37: Facebook | N37: 930.3
A38: ORD200036 | B38: 45785 | C38: C59337 | D38: Laptop | E38: 2 | F38: 534.43 | G38: 465 Main St | H38: Debit Card | I38: Pending | J38: TRK50961250 | K38: 5 | M38: Facebook | N38: 1068.86
A39: ORD200037 | B39: 45579 | C39: C10054 | D39: Laptop | E39: 2 | F39: 76.74 | G39: 409 Main St | H39: Cash | I39: Returned | J39: TRK94005261 | K39: 7 | L39: SAVE10 | M39: Instagram | N39: 153.48
A40: ORD200038 | B40: 45645 | C40: C15924 | D40: Laptop | E40: 1 | F40: 245.89 | G40: 549 Main St | H40: Debit Card | I40: Delivered | J40: TRK14835975 | K40: 3 | L40: SAVE10 | M40: Google | N40: 245.89
...

Sheet Cleaned Sheet
A1: OrderID | B1: Date | C1: Month | D1: Year | E1: Quarter | F1: CustomerID | G1: Product | H1: Quantity | I1: Unit Price | J1: Shipping Address | K1: Payment Method | L1: Order Status | M1: Tracking Number | N1: Items In Cart | O1: Coupon Code | P1: Referral Source | Q1: Total Price
A2: ORD200000 | B2: 44930 | C2: =TEXT(B2,"MMM") -> Jan | D2: =TEXT(B2,"YYYY") -> 2023 | E2: ="Q"&ROUNDUP(MONTH(B2)/3,0) -> Q1 | F2: C72649 | G2: Monitor | H2: 5 | I2: 570.62 | J2: 928 Main St | K2: Debit Card | L2: Shipped | M2: TRK37947903 | N2: 7 | O2: SAVE10 | P2: Instagram | Q2: 2853.1
A3: ORD200001 | B3: 45527 | C3: =TEXT(B3,"MMM") -> Aug | D3: =TEXT(B3,"YYYY") -> 2024 | E3: ="Q"&ROUNDUP(MONTH(B3)/3,0) -> Q3 | F3: C75739 | G3: Phone | H3: 2 | I3: 151.35 | J3: 823 Main St | K3: Online | L3: Shipped | M3: TRK91186779 | N3: 3 | O3: SAVE10 | P3: Referral | Q3: 302.7
A4: ORD200002 | B4: 45349 | C4: =TEXT(B4,"MMM") -> Feb | D4: =TEXT(B4,"YYYY") -> 2024 | E4: ="Q"&ROUNDUP(MONTH(B4)/3,0) -> Q1 | F4: C81728 | G4: Tablet | H4: 5 | I4: 550.68 | J4: 512 Main St | K4: Credit Card | L4: Cancelled | M4: TRK42903982 | N4: 8 | O4: FREESHIP | P4: Email | Q4: 2753.4
A5: ORD200003 | B5: 45214 | C5: =TEXT(B5,"MMM") -> Oct | D5: =TEXT(B5,"YYYY") -> 2023 | E5: ="Q"&ROUNDUP(MONTH(B5)/3,0) -> Q4 | F5: C33540 | G5: Chair | H5: 1 | I5: 273.19 | J5: 275 Main St | K5: Debit Card | L5: Returned | M5: TRK62788070 | N5: 5 | O5: SAVE10 | P5: Facebook | Q5: 273.19
A6: ORD200004 | B6: 45785 | C6: =TEXT(B6,"MMM") -> May | D6: =TEXT(B6,"YYYY") -> 2025 | E6: ="Q"&ROUNDUP(MONTH(B6)/3,0) -> Q2 | F6: C81840 | G6: Printer | H6: 4 | I6: 626.01 | J6: 668 Main St | K6: Online | L6: Delivered | M6: TRK29241424 | N6: 8 | O6: SAVE10 | P6: Email | Q6: 2504.04
A7: ORD200005 | B7: 45222 | C7: =TEXT(B7,"MMM") -> Oct | D7: =TEXT(B7,"YYYY") -> 2023 | E7: ="Q"&ROUNDUP(MONTH(B7)/3,0) -> Q4 | F7: C37249 | G7: Phone | H7: 2 | I7: 245.86 | J7: 934 Main St | K7: Credit Card | L7: Shipped | M7: TRK72976927 | N7: 4 | O7: SAVE10 | P7: Instagram | Q7: 491.72
A8: ORD200006 | B8: 45825 | C8: =TEXT(B8,"MMM") -> Jun | D8: =TEXT(B8,"YYYY") -> 2025 | E8: ="Q"&ROUNDUP(MONTH(B8)/3,0) -> Q2 | F8: C83492 | G8: Laptop | H8: 1 | I8: 664.42 | J8: 986 Main St | K8: Gift Card | L8: Returned | M8: TRK96417362 | N8: 6 | O8: SAVE10 | P8: Facebook | Q8: 664.42
A9: ORD200007 | B9: 45058 | C9: =TEXT(B9,"MMM") -> May | D9: =TEXT(B9,"YYYY") -> 2023 | E9: ="Q"&ROUNDUP(MONTH(B9)/3,0) -> Q2 | F9: C41460 | G9: Monitor | H9: 5 | I9: 149.55 | J9: 706 Main St | K9: Cash | L9: Shipped | M9: TRK78809193 | N9: 9 | O9: FREESHIP | P9: Facebook | Q9: 747.75
A10: ORD200008 | B10: 45749 | C10: =TEXT(B10,"MMM") -> Apr | D10: =TEXT(B10,"YYYY") -> 2025 | E10: ="Q"&ROUNDUP(MONTH(B10)/3,0) -> Q2 | F10: C26817 | G10: Phone | H10: 2 | I10: 134.28 | J10: 904 Main St | K10: Gift Card | L10: Cancelled | M10: TRK61042692 | N10: 2 | O10: No Coupon | P10: Email | Q10: 268.56
A11: ORD200009 | B11: 45251 | C11: =TEXT(B11,"MMM") -> Nov | D11: =TEXT(B11,"YYYY") -> 2023 | E11: ="Q"&ROUNDUP(MONTH(B11)/3,0) -> Q4 | F11: C31946 | G11: Desk | H11: 4 | I11: 509.38 | J11: 102 Main St | K11: Credit Card | L11: Shipped | M11: TRK33478363 | N11: 6 | O11: SAVE10 | P11: Google | Q11: 2037.52
A12: ORD200010 | B12: 45289 | C12: =TEXT(B12,"MMM") -> Dec | D12: =TEXT(B12,"YYYY") -> 2023 | E12: ="Q"&ROUNDUP(MONTH(B12)/3,0) -> Q4 | F12: C43443 | G12: Tablet | H12: 5 | I12: 625.97 | J12: 333 Main St | K12: Credit Card | L12: Returned | M12: TRK98859248 | N12: 9 | O12: WINTER15 | P12: Instagram | Q12: 3129.85
A13: ORD200011 | B13: 45339 | C13: =TEXT(B13,"MMM") -> Feb | D13: =TEXT(B13,"YYYY") -> 2024 | E13: ="Q"&ROUNDUP(MONTH(B13)/3,0) -> Q1 | F13: C93861 | G13: Monitor | H13: 3 | I13: 49.14 | J13: 831 Main St | K13: Online | L13: Returned | M13: TRK48234646 | N13: 7 | O13: SAVE10 | P13: Email | Q13: 147.42
... A1201: ORD201199 | B1201: 45088 | C1201: =TEXT(B1201,"MMM") -> Jun | D1201: =TEXT(B1201,"YYYY") -> 2023 | E1201: ="Q"&ROUNDUP(MONTH(B1201)/3,0) -> Q2 | F1201: C57502 | G1201: Tablet | H1201: 4 | I1201: 560.58 | J1201: 201 Main St | K1201: Gift Card | L1201: Returned | M1201: TRK51116746 | N1201: 6 | O1201: SAVE10 | P1201: Referral | Q1201: 2242.32

Sheet Outlier Check
A1: OrderID | B1: Date | C1: Month | D1: Year | E1: CustomerID | F1: Product | G1: Quantity | H1: Unit Price | I1: Shipping Address | J1: Payment Method | K1: Order Status | L1: Tracking Number | M1: Items In Cart | N1: Coupon Code | O1: Referral Source | P1: Total Price | Q1: Total Price Outlier Check | R1: Quantity Outlier Check | S1: Unit Price Outlier Check
A2: ORD200000 | B2: 44930 | C2: =TEXT(B2,"MMM") -> Jan | D2: =TEXT(B2,"YYYY") -> 2023 | E2: C72649 | F2: Monitor | G2: 5 | H2: 570.62 | I2: 928 Main St | J2: Debit Card | K2: Shipped | L2: TRK37947903 | M2: 7 | N2: SAVE10 | O2: Instagram | P2: 2853.1 | Q2: =IF(OR(P2<'Descriptive Statistics'!$H$17,P2>'Descriptive Statistics'!$H$18),"Potential Outlier","Within Range") -> Within Range | R2: =IF(OR(G2<'Descriptive Statistics'!$I$17,G2>'Descriptive Statistics'!$I$18),"Potential Outlier","Within Range") -> Within Range | S2: =IF(OR(H2<'Descriptive Statistics'!$J$17,H2>'Descriptive Statistics'!$J$18),"Potential Outlier","Within Range") -> Within Range
A3: ORD200001 | B3: 45527 | C3: =TEXT(B3,"MMM") -> Aug | D3: =TEXT(B3,"YYYY") -> 2024 | E3: C75739 | F3: Phone | G3: 2 | H3: 151.35 | I3: 823 Main St | J3: Online | K3: Shipped | L3: TRK91186779 | M3: 3 | N3: SAVE10 | O3: Referral | P3: 302.7 | Q3: =IF(OR(P3<'Descriptive Statistics'!$H$17,P3>'Descriptive Statistics'!$H$18),"Potential Outlier","Within Range") -> Within Range | R3: =IF(OR(G3<'Descriptive Statistics'!$I$17,G3>'Descriptive Statistics'!$I$18),"Potential Outlier","Within Range") -> Within Range | S3: =IF(OR(H3<'Descriptive Statistics'!$J$17,H3>'Descriptive Statistics'!$J$18),"Potential Outlier","Within Range") -> Within Range
A4: ORD200002 | B4: 45349 | C4: =TEXT(B4,"MMM") -> Feb | D4: =TEXT(B4,"YYYY") -> 2024 | E4: C81728 | F4: Tablet | G4: 5 | H4: 550.68 | I4: 512 Main St | J4: Credit Card | K4: Cancelled | L4: TRK42903982 | M4: 8 | N4: FREESHIP | O4: Email | P4: 2753.4 | Q4: =IF(OR(P4<'Descriptive Statistics'!$H$17,P4>'Descriptive Statistics'!$H$18),"Potential Outlier","Within Range") -> Within Range | R4: =IF(OR(G4<'Descriptive Statistics'!$I$17,G4>'Descriptive Statistics'!$I$18),"Potential Outlier","Within Range") -> Within Range | S4: =IF(OR(H4<'Descriptive Statistics'!$J$17,H4>'Descriptive Statistics'!$J$18),"Potential Outlier","Within Range") -> Within Range
A5: ORD200003 | B5: 45214 | C5: =TEXT(B5,"MMM") -> Oct | D5: =TEXT(B5,"YYYY") -> 2023 | E5: C33540 | F5: Chair | G5: 1 | H5: 273.19 | I5: 275 Main St | J5: Debit Card | K5: Returned | L5: TRK62788070 | M5: 5 | N5: SAVE10 | O5: Facebook | P5: 273.19 | Q5: =IF(OR(P5<'Descriptive Statistics'!$H$17,P5>'Descriptive Statistics'!$H$18),"Potential Outlier","Within Range") -> Within Range | R5: =IF(OR(G5<'Descriptive Statistics'!$I$17,G5>'Descriptive Statistics'!$I$18),"Potential Outlier","Within Range") -> Within Range | S5: =IF(OR(H5<'Descriptive Statistics'!$J$17,H5>'Descriptive Statistics'!$J$18),"Potential Outlier","Within Range") -> Within Range
A6: ORD200004 | B6: 45785 | C6: =TEXT(B6,"MMM") -> May | D6: =TEXT(B6,"YYYY") -> 2025 | E6: C81840 | F6: Printer | G6: 4 | H6: 626.01 | I6: 668 Main St | J6: Online | K6: Delivered | L6: TRK29241424 | M6: 8 | N6: SAVE10 | O6: Email | P6: 2504.04 | Q6: =IF(OR(P6<'Descriptive Statistics'!$H$17,P6>'Descriptive Statistics'!$H$18),"Potential Outlier","Within Range") -> Within Range | R6: =IF(OR(G6<'Descriptive Statistics'!$I$17,G6>'Descriptive Statistics'!$I$18),"Potential Outlier","Within Range") -> Within Range | S6: =IF(OR(H6<'Descriptive Statistics'!$J$17,H6>'Descriptive Statistics'!$J$18),"Potential Outlier","Within Range") -> Within Range
A7: ORD200005 | B7: 45222 | C7: =TEXT(B7,"MMM") -> Oct | D7: =TEXT(B7,"YYYY") -> 2023 | E7: C37249 | F7: Phone | G7: 2 | H7: 245.86 | I7: 934 Main St | J7: Credit Card | K7: Shipped | L7: TRK72976927 | M7: 4 | N7: SAVE10 | O7: Instagram | P7: 491.72 | Q7: =IF(OR(P7<'Descriptive Statistics'!$H$17,P7>'Descriptive Statistics'!$H$18),"Potential Outlier","Within Range") -> Within Range | R7: =IF(OR(G7<'Descriptive Statistics'!$I$17,G7>'Descriptive Statistics'!$I$18),"Potential Outlier","Within Range") -> Within Range | S7: =IF(OR(H7<'Descriptive Statistics'!$J$17,H7>'Descriptive Statistics'!$J$18),"Potential Outlier","Within Range") -> Within Range
A8: ORD200006 | B8: 45825 | C8: =TEXT(B8,"MMM") -> Jun | D8: =TEXT(B8,"YYYY") -> 2025 | E8: C83492 | F8: Laptop | G8: 1 | H8: 664.42 | I8: 986 Main St | J8: Gift Card | K8: Returned | L8: TRK96417362 | M8: 6 | N8: SAVE10 | O8: Facebook | P8: 664.42 | Q8: =IF(OR(P8<'Descriptive Statistics'!$H$17,P8>'Descriptive Statistics'!$H$18),"Potential Outlier","Within Range") -> Within Range | R8: =IF(OR(G8<'Descriptive Statistics'!$I$17,G8>'Descriptive Statistics'!$I$18),"Potential Outlier","Within Range") -> Within Range | S8: =IF(OR(H8<'Descriptive Statistics'!$J$17,H8>'Descriptive Statistics'!$J$18),"Potential Outlier","Within Range") -> Within Range
A9: ORD200007 | B9: 45058 | C9: =TEXT(B9,"MMM") -> May | D9: =TEXT(B9,"YYYY") -> 2023 | E9: C41460 | F9: Monitor | G9: 5 | H9: 149.55 | I9: 706 Main St | J9: Cash | K9: Shipped | L9: TRK78809193 | M9: 9 | N9: FREESHIP | O9: Facebook | P9: 747.75 | Q9: =IF(OR(P9<'Descriptive Statistics'!$H$17,P9>'Descriptive Statistics'!$H$18),"Potential Outlier","Within Range") -> Within Range | R9: =IF(OR(G9<'Descriptive Statistics'!$I$17,G9>'Descriptive Statistics'!$I$18),"Potential Outlier","Within Range") -> Within Range | S9: =IF(OR(H9<'Descriptive Statistics'!$J$17,H9>'Descriptive Statistics'!$J$18),"Potential Outlier","Within Range") -> Within Range
A10: ORD200008 | B10: 45749 | C10: =TEXT(B10,"MMM") -> Apr | D10: =TEXT(B10,"YYYY") -> 2025 | E10: C26817 | F10: Phone | G10: 2 | H10: 134.28 | I10: 904 Main St | J10: Gift Card | K10: Cancelled | L10: TRK61042692 | M10: 2 | N10: No Coupon | O10: Email | P10: 268.56 | Q10: =IF(OR(P10<'Descriptive Statistics'!$H$17,P10>'Descriptive Statistics'!$H$18),"Potential Outlier","Within Range") -> Within Range | R10: =IF(OR(G10<'Descriptive Statistics'!$I$17,G10>'Descriptive Statistics'!$I$18),"Potential Outlier","Within Range") -> Within Range | S10: =IF(OR(H10<'Descriptive Statistics'!$J$17,H10>'Descriptive Statistics'!$J$18),"Potential Outlier","Within Range") -> Within Range
A11: ORD200009 | B11: 45251 | C11: =TEXT(B11,"MMM") -> Nov | D11: =TEXT(B11,"YYYY") -> 2023 | E11: C31946 | F11: Desk | G11: 4 | H11: 509.38 | I11: 102 Main St | J11: Credit Card | K11: Shipped | L11: TRK33478363 | M11: 6 | N11: SAVE10 | O11: Google | P11: 2037.52 | Q11: =IF(OR(P11<'Descriptive Statistics'!$H$17,P11>'Descriptive Statistics'!$H$18),"Potential Outlier","Within Range") -> Within Range | R11: =IF(OR(G11<'Descriptive Statistics'!$I$17,G11>'Descriptive Statistics'!$I$18),"Potential Outlier","Within Range") -> Within Range | S11: =IF(OR(H11<'Descriptive Statistics'!$J$17,H11>'Descriptive Statistics'!$J$18),"Potential Outlier","Within Range") -> Within Range
A12: ORD200010 | B12: 45289 | C12: =TEXT(B12,"MMM") -> Dec | D12: =TEXT(B12,"YYYY") -> 2023 | E12: C43443 | F12: Tablet | G12: 5 | H12: 625.97 | I12: 333 Main St | J12: Credit Card | K12: Returned | L12: TRK98859248 | M12: 9 | N12: WINTER15 | O12: Instagram | P12: 3129.85 | Q12: =IF(OR(P12<'Descriptive Statistics'!$H$17,P12>'Descriptive Statistics'!$H$18),"Potential Outlier","Within Range") -> Within Range | R12: =IF(OR(G12<'Descriptive Statistics'!$I$17,G12>'Descriptive Statistics'!$I$18),"Potential Outlier","Within Range") -> Within Range | S12: =IF(OR(H12<'Descriptive Statistics'!$J$17,H12>'Descriptive Statistics'!$J$18),"Potential Outlier","Within Range") -> Within Range
A13: ORD200011 | B13: 45339 | C13: =TEXT(B13,"MMM") -> Feb | D13: =TEXT(B13,"YYYY") -> 2024 | E13: C93861 | F13: Monitor | G13: 3 | H13: 49.14 | I13: 831 Main St | J13: Online | K13: Returned | L13: TRK48234646 | M13: 7 | N13: SAVE10 | O13: Email | P13: 147.42 | Q13: =IF(OR(P13<'Descriptive Statistics'!$H$17,P13>'Descriptive Statistics'!$H$18),"Potential Outlier","Within Range") -> Within Range | R13: =IF(OR(G13<'Descriptive Statistics'!$I$17,G13>'Descriptive Statistics'!$I$18),"Potential Outlier","Within Range") -> Within Range | S13: =IF(OR(H13<'Descriptive Statistics'!$J$17,H13>'Descriptive Statistics'!$J$18),"Potential Outlier","Within Range") -> Within Range
... A1201: ORD201199 | B1201: 45088 | C1201: =TEXT(B1201,"MMM") -> Jun | D1201: =TEXT(B1201,"YYYY") -> 2023 | E1201: C57502 | F1201: Tablet | G1201: 4 | H1201: 560.58 | I1201: 201 Main St | J1201: Gift Card | K1201: Returned | L1201: TRK51116746 | M1201: 6 | N1201: SAVE10 | O1201: Referral | P1201: 2242.32 | Q1201: =IF(OR(P1201<'Descriptive Statistics'!$H$17,P1201>'Descriptive Statistics'!$H$18),"Potential Outlier","Within Range") -> Within Range | R1201: =IF(OR(G1201<'Descriptive Statistics'!$I$17,G1201>'Descriptive Statistics'!$I$18),"Potential Outlier","Within Range") -> Within Range | S1201: =IF(OR(H1201<'Descriptive Statistics'!$J$17,H1201>'Descriptive Statistics'!$J$18),"Potential Outlier","Within Range") -> Within Range

Sheet Descriptive Statistics
A2: Measure | B2: Values | D2: Total Price Statistics | E2: Values | G2: Quantity Statistics | H2: Values | J2: Cart Items Statistics | K2: Values
A3: Total Orders | B3: =COUNTA('Cleaned Sheet'!A2:A1201) -> 1200 | D3: Total Price Average | E3: =AVERAGE('Cleaned Sheet'!Q2:Q1201) -> 1053.9683 | G3: Total quantity | H3: =SUM('Cleaned Sheet'!H2:H1201) -> 3535 | J3: Total | K3: =SUM('Cleaned Sheet'!N2:N1201) -> 6582
A4: Total Customers | B4: {=COUNTA(_xlfn.UNIQUE('Cleaned Sheet'!F2:F1201))} -> 1189 | D4: Total Price Median | E4: =MEDIAN('Cleaned Sheet'!Q2:Q1201) -> 823.615 | G4: Average | H4: =AVERAGE('Cleaned Sheet'!H2:H1201) -> 2.9458333 | J4: Average | K4: =AVERAGE('Cleaned Sheet'!N2:N1201) -> 5.485
A5: Gross Revenue | B5: =SUM('Cleaned Sheet'!Q2:Q1201) -> 1264762 | D5: Total Price Max | E5: =MAX('Cleaned Sheet'!Q2:Q1201) -> 3456.4 | G5: Median | H5: =MEDIAN('Cleaned Sheet'!H2:H1201) -> 3 | J5: Median | K5: =MEDIAN('Cleaned Sheet'!N2:N1201) -> 5
D6: Total Price Min | E6: =MIN('Cleaned Sheet'!Q2:Q1201) -> 11.39 | G6: Min | H6: =MIN('Cleaned Sheet'!H2:H1201) -> 1 | J6: Min | K6: =MIN('Cleaned Sheet'!N2:N1201) -> 1
A7: KPI | B7: Values | D7: Standard Deviation | E7: =_xlfn.STDEV.S('Cleaned Sheet'!Q2:Q1201) -> 819.85656 | G7: Max | H7: =MAX('Cleaned Sheet'!H2:H1201) -> 5 | J7: Max | K7: =MAX('Cleaned Sheet'!N2:N1201) -> 10
A8: Shipped | B8: =SUMIF('Cleaned Sheet'!L2:L1201,"Shipped",'Cleaned Sheet'!Q2:Q1201) -> 246159.58 | G8: Mode | H8: {=MODE('Cleaned Sheet'!H2:H1201)} -> 1 | J8: Mode | K8: {=MODE('Cleaned Sheet'!N2:N1201)} -> 5
A9: Delivered | B9: =SUMIF('Cleaned Sheet'!L2:L1201,"Delivered",'Cleaned Sheet'!Q2:Q1201) -> 242600.32 | G9: Standard Deviation | H9: =_xlfn.STDEV.S('Cleaned Sheet'!H2:H1201) -> 1.4075571 | J9: Standard Deviation | K9: =_xlfn.STDEV.S('Cleaned Sheet'!N2:N1201) -> 2.2819833
A10: Returned | B10: =SUMIF('Cleaned Sheet'!L2:L1201,"Returned",'Cleaned Sheet'!Q2:Q1201) -> 243277.7 | D10: Unit Price | E10: Values
A11: Actual Revenue | B11: =SUM(B8,B9) -> 488759.9 | D11: Total | E11: =SUM('Cleaned Sheet'!I2:I1201) -> 427695.3
A12: Average Order Value | B12: =B11/(COUNTIF('Cleaned Sheet'!L2:L1201,"Shipped")+COUNTIF('Cleaned Sheet'!L2:L1201,"Delivered")) -> 1048.841 | D12: Average | E12: =AVERAGE('Cleaned Sheet'!I1:I1201) -> 356.41275 | G12: Outlier Check | H12: Total Price | I12: Quantity | J12: Unit Price
A13: Return Rate | B13: =COUNTIF('Cleaned Sheet'!L2:L1201,"Returned")/COUNTA('Cleaned Sheet'!L2:L1201) -> 0.20583333 | D13: Median | E13: =MEDIAN('Cleaned Sheet'!I2:I1201) -> 364.21 | G13: Metric | H13: Total Price | I13: Quantity | J13: Unit Price
A14: Cancelled Rate | B14: =COUNTIF('Cleaned Sheet'!L2:L1201,"Cancelled")/COUNTA('Cleaned Sheet'!L2:L1201) -> 0.20833333 | D14: Max | E14: =MAX('Cleaned Sheet'!I2:I1201) -> 699.93 | G14: Outlier(Q1) | H14: =QUARTILE('Cleaned Sheet'!Q2:Q1201,1) -> 410.52 | I14: =QUARTILE('Cleaned Sheet'!H2:H1201,1) -> 2 | J14: =QUARTILE('Cleaned Sheet'!I2:I1201,1) -> 186.0625
D15: Min | E15: =MIN('Cleaned Sheet'!I2:I1201) -> 11.39 | G15: Outlier(Q3) | H15: =QUARTILE('Cleaned Sheet'!Q2:Q1201,3) -> 1578.475 | I15: =QUARTILE('Cleaned Sheet'!H2:H1201,3) -> 4 | J15: =QUARTILE('Cleaned Sheet'!I2:I1201,3) -> 521.57
D16: SD | E16: =_xlfn.STDEV.S('Cleaned Sheet'!I2:I1201) -> 197.17715 | G16: IQR | H16: =H15-H14 -> 1167.955 | I16: =I15-I14 -> 2 | J16: =J15-J14 -> 335.5075
G17: Lower bound | H17: =H14-(1.5*H16) -> -1341.4125 | I17: =I14-(1.5*I16) -> -1 | J17: =J14-(1.5*J16) -> -317.19875
A18: Quarter | B18: Revenue | C18: Orders | D18: AOV | G18: Upper bound | H18: =H15+(1.5*H16) -> 3330.4075 | I18: =I15+(1.5*I16) -> 7 | J18: =J15+(1.5*J16) -> 1024.8312
A19: 2023 Q1 | B19: =SUMIFS('Cleaned Sheet'!Q:Q,'Cleaned Sheet'!D:D,"2023",'Cleaned Sheet'!E:E,"Q1") -> 145412.78 | C19: =COUNTIFS('Cleaned Sheet'!$D$2:$D$1201,"2023",'Cleaned Sheet'!$E$2:$E$1201,"Q1") -> 127 | D19: =B19/C19 -> 1144.9825
A20: 2023 Q2 | B20: =SUMIFS('Cleaned Sheet'!Q:Q,'Cleaned Sheet'!D:D,"2023",'Cleaned Sheet'!E:E,"Q2") -> 141088.74 | C20: =COUNTIFS('Cleaned Sheet'!$D$2:$D$1201,"2023",'Cleaned Sheet'!$E$2:$E$1201,"Q2") -> 125 | D20: =B20/C20 -> 1128.7099
A21: 2023 Q3 | B21: =SUMIFS('Cleaned Sheet'!Q:Q,'Cleaned Sheet'!D:D,"2023",'Cleaned Sheet'!E:E,"Q3") -> 126699.47 | C21: =COUNTIFS('Cleaned Sheet'!$D$2:$D$1201,"2023",'Cleaned Sheet'!$E$2:$E$1201,"Q3") -> 124 | D21: =B21/C21 -> 1021.7699
A22: 2023 Q4 | B22: =SUMIFS('Cleaned Sheet'!Q:Q,'Cleaned Sheet'!D:D,"2023",'Cleaned Sheet'!E:E,"Q4") -> 139442.25 | C22: =COUNTIFS('Cleaned Sheet'!$D$2:$D$1201,"2023",'Cleaned Sheet'!$E$2:$E$1201,"Q4") -> 134 | D22: =B22/C22 -> 1040.6138
A23: 2024 Q1 | B23: =SUMIFS('Cleaned Sheet'!Q:Q,'Cleaned Sheet'!D:D,"2024",'Cleaned Sheet'!E:E,"Q1") -> 111468.55 | C23: =COUNTIFS('Cleaned Sheet'!$D$2:$D$1201,"2024",'Cleaned Sheet'!$E$2:$E$1201,"Q1") -> 100 | D23: =B23/C23 -> 1114.6855
A24: 2024 Q2 | B24: =SUMIFS('Cleaned Sheet'!Q:Q,'Cleaned Sheet'!D:D,"2024",'Cleaned Sheet'!E:E,"Q2") -> 145590.79 | C24: =COUNTIFS('Cleaned Sheet'!$D$2:$D$1201,"2024",'Cleaned Sheet'!$E$2:$E$1201,"Q2") -> 137 | D24: =B24/C24 -> 1062.7065
A25: 2024 Q3 | B25: =SUMIFS('Cleaned Sheet'!Q:Q,'Cleaned Sheet'!D:D,"2024",'Cleaned Sheet'!E:E,"Q3") -> 114750.03 | C25: =COUNTIFS('Cleaned Sheet'!$D$2:$D$1201,"2024",'Cleaned Sheet'!$E$2:$E$1201,"Q3") -> 115 | D25: =B25/C25 -> 997.82635
A26: 2024 Q4 | B26: =SUMIFS('Cleaned Sheet'!Q:Q,'Cleaned Sheet'!D:D,"2024",'Cleaned Sheet'!E:E,"Q4") -> 108426.5 | C26: =COUNTIFS('Cleaned Sheet'!$D$2:$D$1201,"2024",'Cleaned Sheet'!$E$2:$E$1201,"Q4") -> 107 | D26: =B26/C26 -> 1013.3318
A27: 2025 Q1 | B27: =SUMIFS('Cleaned Sheet'!Q:Q,'Cleaned Sheet'!D:D,"2025",'Cleaned Sheet'!E:E,"Q1") -> 103617.61 | C27: =COUNTIFS('Cleaned Sheet'!$D$2:$D$1201,"2025",'Cleaned Sheet'!$E$2:$E$1201,"Q1") -> 113 | D27: =B27/C27 -> 916.97
A28: 2025 Q2 | B28: =SUMIFS('Cleaned Sheet'!Q:Q,'Cleaned Sheet'!D:D,"2025",'Cleaned Sheet'!E:E,"Q2") -> 128265.24 | C28: =COUNTIFS('Cleaned Sheet'!$D$2:$D$1201,"2025",'Cleaned Sheet'!$E$2:$E$1201,"Q2") -> 118 | D28: =B28/C28 -> 1086.9936

Sheet Pivot Tables
A3: Product | B3: % of Product | C3: Count of OrderID | D3: Sum of Unit Price | E3: % of Unit Price | F3: Sum of Total Price | G3: % of Total Price | I3: Payment Method | J3: Count of Payment Method | L3: A: Lower Bound | M3: B: Upper Bound | N3: Bins | O3: C: Frequency
A4: Tablet | B4: 0.14916667 | C4: 179 | D4: 65814.56 | E4: 0.15388189 | F4: 186568.95 | G4: 0.14751309 | I4: Online | J4: 258 | L4: 0 | M4: 500 | N4: =L4&"-"&M4 -> 0-500 | O4: =COUNTIFS('Cleaned Sheet'!$Q$2:$Q$1201,">="&L4,'Cleaned Sheet'!$Q$2:$Q$1201,"<"&M4) -> 383
A5: Printer | B5: 0.15083333 | C5: 181 | D5: 63660.4 | E5: 0.14884522 | F5: 195612.61 | G5: 0.15466358 | I5: Cash | J5: 246 | L5: 500 | M5: 1000 | N5: =L5&"-"&M5 -> 500-1000 | O5: =COUNTIFS('Cleaned Sheet'!$Q$2:$Q$1201,">="&L5,'Cleaned Sheet'!$Q$2:$Q$1201,"<"&M5) -> 305
A6: Phone | B6: 0.13 | C6: 156 | D6: 58533.94 | E6: 0.13685897 | F6: 151722.39 | G6: 0.11996122 | I6: Credit Card | J6: 234 | L6: 1000 | M6: 1500 | N6: =L6&"-"&M6 -> 1000-1500 | O6: =COUNTIFS('Cleaned Sheet'!$Q$2:$Q$1201,">="&L6,'Cleaned Sheet'!$Q$2:$Q$1201,"<"&M6) -> 190
A7: Monitor | B7: 0.13583333 | C7: 163 | D7: 58462.17 | E7: 0.13669117 | F7: 175651.41 | G7: 0.138881 | I7: Debit Card | J7: 232 | L7: 1500 | M7: 2000 | N7: =L7&"-"&M7 -> 1500-2000 | O7: =COUNTIFS('Cleaned Sheet'!$Q$2:$Q$1201,">="&L7,'Cleaned Sheet'!$Q$2:$Q$1201,"<"&M7) -> 142
A8: Laptop | B8: 0.14416667 | C8: 173 | D8: 61883.32 | E8: 0.1446902 | F8: 192126.56 | G8: 0.15190729 | I8: Gift Card | J8: 230 | L8: 2000 | M8: 2500 | N8: =L8&"-"&M8 -> 2000-2500 | O8: =COUNTIFS('Cleaned Sheet'!$Q$2:$Q$1201,">="&L8,'Cleaned Sheet'!$Q$2:$Q$1201,"<"&M8) -> 86
A9: Desk | B9: 0.14166667 | C9: 170 | D9: 56033.38 | E9: 0.13101238 | F9: 167459.93 | G9: 0.13240431 | I9: Grand Total | J9: 1200 | L9: 2500 | M9: 3000 | N9: =L9&"-"&M9 -> 2500-3000 | O9: =COUNTIFS('Cleaned Sheet'!$Q$2:$Q$1201,">="&L9,'Cleaned Sheet'!$Q$2:$Q$1201,"<"&M9) -> 60
A10: Chair | B10: 0.14833333 | C10: 178 | D10: 63307.53 | E10: 0.14802017 | F10: 195620.11 | G10: 0.15466951 | L10: 3000 | M10: 3500 | N10: =L10&"-"&M10 -> 3000-3500 | O10: =COUNTIFS('Cleaned Sheet'!$Q$2:$Q$1201,">="&L10,'Cleaned Sheet'!$Q$2:$Q$1201,"<"&M10) -> 34
A11: Grand Total | B11: 1 | C11: 1200 | D11: 427695.3 | E11: 1 | F11: 1264762 | G11: 1 | L11: 3500 | M11: 4000 | N11: =L11&"-"&M11 -> 3500-4000 | O11: =COUNTIFS('Cleaned Sheet'!$Q$2:$Q$1201,">="&L11,'Cleaned Sheet'!$Q$2:$Q$1201,"<"&M11) -> 0
A13: Order Status | B13: Count of Order Status | D13: Coupon Code | E13: Count of Coupon Code | G13: Referral Source | H13: Count of Referral Source | L13: Bins | M13: Sum of C: Frequency
A14: Cancelled | B14: 250 | D14: FREESHIP | E14: 313 | G14: Instagram | H14: 259 | L14: 0-500 | M14: 383
A15: Returned | B15: 247 | D15: No Coupon | E15: 309 | G15: Email | H15: 250 | L15: 500-1000 | M15: 305
A16: Pending | B16: 237 | D16: WINTER15 | E16: 292 | G16: Google | H16: 241 | L16: 1000-1500 | M16: 190
A17: Shipped | B17: 235 | D17: SAVE10 | E17: 286 | G17: Facebook | H17: 228 | L17: 1500-2000 | M17: 142
A18: Delivered | B18: 231 | D18: Grand Total | E18: 1200 | G18: Referral | H18: 222 | L18: 2000-2500 | M18: 86
A19: Grand Total | B19: 1200 | G19: Grand Total | H19: 1200 | L19: 2500-3000 | M19: 60
L20: 3000-3500 | M20: 34
A21: Product | B21: Revenue | D21: Product | E21: Count of OrderID | G21: Year | H21: Month | I21: Count of OrderID | L21: 3500-4000 | M21: 0
A22: Chair | B22: 195620.11 | D22: Printer | E22: 181 | G22: 2023 | I22: 510 | L22: Grand Total | M22: 1200
A23: Printer | B23: 195612.61 | D23: Tablet | E23: 179 | H23: Jan | I23: 47
A24: Laptop | B24: 192126.56 | D24: Chair | E24: 178 | H24: Feb | I24: 37
A25: Tablet | B25: 186568.95 | D25: Laptop | E25: 173 | H25: Mar | I25: 43
A26: Monitor | B26: 175651.41 | D26: Desk | E26: 170 | H26: Apr | I26: 31
A27: Desk | B27: 167459.93 | D27: Monitor | E27: 163 | H27: May | I27: 49
A28: Phone | B28: 151722.39 | D28: Phone | E28: 156 | H28: Jun | I28: 45
A29: Grand Total | B29: 1264762 | D29: Grand Total | E29: 1200 | H29: Jul | I29: 44
H30: Aug | I30: 51
A31: Year | B31: Quarter | C31: Sum of Total Price | H31: Sep | I31: 29
A32: 2023 | C32: 552643.24 | H32: Oct | I32: 47
B33: Q1 | C33: 145412.78 | H33: Nov | I33: 41
B34: Q2 | C34: 141088.74 | H34: Dec | I34: 46
B35: Q3 | C35: 126699.47 | G35: 2024 | I35: 459
B36: Q4 | C36: 139442.25 | H36: Jan | I36: 32
A37: 2024 | C37: 480235.87 | H37: Feb | I37: 32
B38: Q1 | C38: 111468.55 | H38: Mar | I38: 36
B39: Q2 | C39: 145590.79 | H39: Apr | I39: 50
B40: Q3 | C40: 114750.03 | H40: May | I40: 34
B41: Q4 | C41: 108426.5 | H41: Jun | I41: 53
A42: 2025 | C42: 231882.85 | H42: Jul | I42: 43
B43: Q1 | C43: 103617.61 | H43: Aug | I43: 28
...

Sheet Main Dashboard
AB46: s

Sheet Summary
A1: S/N | B1: Area | C1: Finding | D1: Evidence | E1: Source in workbook
A2: 1 | B2: Order outcomes | C2: 41.4% of orders are cancelled or returned | D2: Cancelled 20.83%, Returned 20.58% | E2: Descriptive Statistics, KPI block (rates)
A3: 2 | B3: Revenue | C3: Only 38.6% of gross revenue is realised | D3: Net $488,759.90 vs gross $1,264,761.96 | E3: Descriptive Statistics, Gross Revenue and Actual Revenue
A4: 3 | B4: AOV | C4: Net average order value is about $1,049 | D4: $1,048.84 (466 Shipped and Delivered orders) | E4: Descriptive Statistics, Average Order Value
A5: 4 | B5: Order value | C5: Right-skewed: a few large orders pull the mean above the median | D5: Mean $1,053.97, median $823.62, SD $819.86 | E5: Descriptive Statistics, Total Price block
A6: 5 | B6: Order value | C6: Most orders are small | D6: 57% under $1,000; 15% over $2,000 | E6: Distribution of Total Order Prices chart
A7: 6 | B7: Price and quantity | C7: Unit price is spread evenly; most orders are 1 to 3 units | D7: Unit price mean $356.41, median $364.21; quantity mean 2.95, mode 1 | E7: Descriptive Statistics, Unit Price and Quantity blocks
A8: 7 | B8: Products | C8: Evenly balanced; ranking gaps are trivial | D8: 13% to 15% of orders each; Chair and Printer revenue differ by $7.50 | E8: Revenue by Product and Orders by Product charts
A9: 8 | B9: Channels | C9: Referral sources are close | D9: Instagram highest (259), Referral lowest (222) | E9: Referral Source chart
A10: 9 | B10: Order trend | C10: Orders slipped slightly (Jan to Jun each year) | D10: 252, then 237, then 231 (-6.0%, then -2.5%) | E10: Quarterly table (Q1 plus Q2 orders)
A11: 10 | B11: Revenue trend | C11: Revenue fell faster than orders | D11: $286,502, then $257,059, then $231,883 (-10.3%, then -9.8%) | E11: Quarterly table (Q1 plus Q2 revenue)
A12: 11 | B12: AOV trend | C12: Volatile, not steadily falling | D12: $1,145 (2023 Q1), low $917 (2025 Q1), back to $1,087 (2025 Q2) | E12: AOV column in the quarterly table and AOV chart
A13: 12 | B13: Seasonality | C13: No consistent seasonal pattern | D13: Monthly orders range 27 (Jan 2025) to 53 (Jun 2024) | E13: Orders by Month chart
... A17: 16 | B17: Limitation | C17: 2025 is a half year; net revenue is a floor | D17: Data ends 30 Jun 2025; 237 Pending orders | E17: Cleaned Sheet
